# üìã Informe de Refactorizaciones encontrados por Pylint

---

## üîß Refactorizaci√≥n #1: Preservaci√≥n de Cadena de Excepciones (W0707)

### Contexto

El m√≥dulo `workouts.py` contiene los endpoints de la API REST para gesti√≥n de entrenamientos. Durante el an√°lisis con Pylint, se detect√≥ que 4 funciones re-lanzaban excepciones sin preservar la cadena de causas original, perdiendo informaci√≥n valiosa de debugging. Este problema se identific√≥ en operaciones CRUD cr√≠ticas que manejan sets de ejercicios.

### Motivos de la Refactorizaci√≥n

#### Problema Detectado

**Error Pylint:**

```
workouts_udec_backend/app/api/endpoints/workouts.py:269:8: W0707: Consider explicitly re-raising using 'raise HTTPException(...) from e'
workouts_udec_backend/app/api/endpoints/workouts.py:297:8: W0707: Consider explicitly re-raising using 'raise HTTPException(...) from e'
workouts_udec_backend/app/api/endpoints/workouts.py:326:8: W0707: Consider explicitly re-raising using 'raise HTTPException(...) from e'
workouts_udec_backend/app/api/endpoints/workouts.py:396:8: W0707: Consider explicitly re-raising using 'raise HTTPException(...) from e'
```

**C√≥digo problem√°tico:**

```python
# L√≠nea 269 - Endpoint add_set_to_exercise()
try:
    return crud.workout.add_set_to_exercise(db, workout_id, exercise_id, set_data)
except ValueError as e:
    raise HTTPException(status_code=404, detail=str(e))  # ‚ùå Pierde stack trace original

# L√≠nea 297 - Endpoint update_exercise_set()
try:
    return crud.workout.update_exercise_set(db, workout_id, exercise_id, set_id, set_in)
except ValueError as e:
    raise HTTPException(status_code=404, detail=str(e))  # ‚ùå Pierde stack trace original

# L√≠nea 326 - Endpoint delete_exercise_set()
try:
    crud.workout.delete_exercise_set(db, workout_id, exercise_id, set_id)
    return {"message": "Exercise set deleted successfully"}
except ValueError as e:
    raise HTTPException(status_code=404, detail=str(e))  # ‚ùå Pierde stack trace original

# L√≠nea 396 - Endpoint update_exercise_notes()
try:
    return crud.workout.update_exercise_notes(db, workout_id, exercise_id, notes_data.get("notes", ""))
except ValueError as e:
    raise HTTPException(status_code=404, detail=str(e))  # ‚ùå Pierde stack trace original
```

#### Impacto del Problema

1. **Debugging dificultado:** Cuando ocurre un error en producci√≥n, los logs solo muestran `HTTPException: 404 Not Found`, sin informaci√≥n sobre la excepci√≥n `ValueError` original que caus√≥ el problema.
2. **P√©rdida de contexto:** Si el error ocurre profundamente en la capa CRUD (ej: dentro de una query SQLAlchemy), el stack trace se trunca y no se puede rastrear el origen exacto del problema.
3. **Violaci√≥n de PEP 3134:** Python 3+ introdujo exception chaining expl√≠cito con `raise ... from ...` para mantener el contexto completo de errores. No usarlo es considerado una mala pr√°ctica.

### Soluci√≥n Propuesta

#### Tipo de Refactorizaci√≥n

**Exception Chaining** - Agregar cl√°usula `from e` para preservar la excepci√≥n original en la cadena de causas.

#### Implementaci√≥n

**Correcci√≥n aplicada en las 4 ocurrencias:**

```python
# DESPU√âS - L√≠nea 269:
try:
    return crud.workout.add_set_to_exercise(db, workout_id, exercise_id, set_data)
except ValueError as e:
    raise HTTPException(status_code=404, detail=str(e)) from e  # ‚úÖ Preserva stack trace

# DESPU√âS - L√≠nea 297:
try:
    return crud.workout.update_exercise_set(db, workout_id, exercise_id, set_id, set_in)
except ValueError as e:
    raise HTTPException(status_code=404, detail=str(e)) from e  # ‚úÖ Preserva stack trace

# DESPU√âS - L√≠nea 326:
try:
    crud.workout.delete_exercise_set(db, workout_id, exercise_id, set_id)
    return {"message": "Exercise set deleted successfully"}
except ValueError as e:
    raise HTTPException(status_code=404, detail=str(e)) from e  # ‚úÖ Preserva stack trace

# DESPU√âS - L√≠nea 396:
try:
    return crud.workout.update_exercise_notes(db, workout_id, exercise_id, notes_data.get("notes", ""))
except ValueError as e:
    raise HTTPException(status_code=404, detail=str(e)) from e  # ‚úÖ Preserva stack trace
```

**Archivos modificados:**

- `workouts_udec_backend/app/api/endpoints/workouts.py` (4 l√≠neas)

**Estad√≠sticas:**

- **Errores W0707 corregidos:** 4/4 (100%)
- **Impacto funcional:** Ninguno (comportamiento id√©ntico para usuarios)
- **Tiempo de implementaci√≥n:** 2 minutos
- **Riesgo:** 0% (cambio puramente aditivo)

#### Ejemplo de Mejora en Debugging

**ANTES (sin exception chaining):**

```python
# Log de error en producci√≥n:
HTTPException: 404 Not Found
  Detail: "Workout exercise with id 123 not found"
  File "workouts.py", line 269, in add_set_to_exercise
    raise HTTPException(status_code=404, detail=str(e))
```

‚ùå **Problema:** No se puede saber QU√â caus√≥ el `ValueError` ni D√ìNDE ocurri√≥ en la capa CRUD.

**DESPU√âS (con exception chaining):**

```python
# Log de error en producci√≥n:
HTTPException: 404 Not Found
  Detail: "Workout exercise with id 123 not found"
  File "workouts.py", line 269, in add_set_to_exercise
    raise HTTPException(status_code=404, detail=str(e)) from e

The above exception was the direct cause of the following exception:

ValueError: Workout exercise with id 123 not found
  File "crud_workout.py", line 234, in add_set_to_exercise
    raise ValueError(f"Workout exercise with id {exercise_id} not found")
  File "crud_workout.py", line 230, in add_set_to_exercise
    if not workout_exercise:
```

‚úÖ **Beneficio:** Stack trace completo muestra que el error se origin√≥ en `crud_workout.py:234` cuando `workout_exercise` era `None`, facilitando la identificaci√≥n del problema.

#### Ventajas de la Soluci√≥n

1. **Monitoreo mejorado:** Herramientas de APM pueden correlacionar errores por su causa ra√≠z, generando mejores m√©tricas y alertas.
2. **Sin impacto funcional:** Los usuarios no perciben ning√∫n cambio en el comportamiento de la API. La respuesta HTTP sigue siendo id√©ntica.
